Workbook
Name NativeTimeline_Date: #N/A
Name Slicer_Region: #N/A

Sheet Dashboard

Sheet Analysis
A1: Raw Data
A3: 1) Date And Time Function
A4: Select Trancation_ID | B4: TRX0127
A11: {=TRANSPOSE(INDIRECT("'"&$A$1&"'!A1:O1"))} -> Transaction_ID | B11: {=TRANSPOSE(_xlfn.XLOOKUP(B4,'Raw Data'!$A$2:$A$251,'Raw Data'!A2:O251))} -> TRX0127 | D11: Transction Month Last Date | F11: =EOMONTH(B12,0) -> 45473
A12: Date | B12: 45472 | D12: Customer Period Time | F12: =DATEDIF(B24,TODAY(),"Y") &" Year " &DATEDIF(B24,TODAY(),"ym")& "Month "&DATEDIF(B24,TODAY(),"md")& "DAYS" -> 3 Year 11Month 23DAYS
A13: Months | B13: June | D13: Current Time and Date | F13: =NOW() -> 46305.37
A14: Customer_ID | B14: CUST030
A15: Customer_Name | B15: Helen Roberts
A16: Product_ID | B16: P008
A17: Product_Name | B17: Bookshelf
A18: Category | B18: Furniture
A19: Quantity | B19: 1
A20: Unit_Price | B20: 149.99
A21: Payment_Method | B21: PayPal
A22: Region | B22: East
A23: Customer_Segment | B23: Basic
A24: Customer_Since | B24: 44851
A25: Total_Amount | B25: 149.99
A28: 2) Filter Function Top 5
A29: Select Region | B29: Central
A32: {=INDIRECT("'"&$A1&"'!A1:O1")} -> Transaction_ID | B32: Date | C32: Months | D32: Customer_ID | E32: Customer_Name | F32: Product_ID | G32: Product_Name | H32: Category | I32: Quantity | J32: Unit_Price | K32: Payment_Method | L32: Region | M32: Customer_Segment | N32: Customer_Since | O32: Total_Amount
A33: {=_xlfn.TAKE(_xlfn._xlws.SORT(_xlfn._xlws.FILTER('Raw Data'!$A$2:$O$251,'Raw Data'!L2:L251=Analysis!B29,"-"),15,-1),5)} -> TRX0030 | B33: 45686 | C33: January | D33: CUST011 | E33: William White | F33: P001 | G33: Laptop | H33: Electronics | I33: 4 | J33: 899.99 | K33: PayPal | L33: Central | M33: Basic | N33: 44734 | O33: 3599.96
A34: TRX0034 | B34: 45581 | C34: October | D34: CUST049 | E34: Raymond Ross | F34: P002 | G34: Smartphone | H34: Electronics | I34: 4 | J34: 699.99 | K34: Credit Card | L34: Central | M34: Basic | N34: 45385 | O34: 2799.96
A35: TRX0144 | B35: 45749 | C35: April | D35: CUST029 | E35: Edward Mitchell | F35: P001 | G35: Laptop | H35: Electronics | I35: 3 | J35: 899.99 | K35: Cash | L35: Central | M35: Standard | N35: 44953 | O35: 2699.97
A36: TRX0125 | B36: 45666 | C36: January | D36: CUST026 | E36: Karen Hill | F36: P002 | G36: Smartphone | H36: Electronics | I36: 3 | J36: 699.99 | K36: Credit Card | L36: Central | M36: Premium | N36: 45105 | O36: 2099.97
A37: TRX0059 | B37: 45673 | C37: January | D37: CUST016 | E37: Elizabeth Hall | F37: P007 | G37: Desk | H37: Furniture | I37: 5 | J37: 299.99 | K37: Debit Card | L37: Central | M37: Basic | N37: 44431 | O37: 1499.95
A41: 3) What-if-Analysis
A42: Product List | B42: Total Amount | C42: Total Quantity
A43: {=_xlfn.UNIQUE('Raw Data'!$G$2:$G$251)} -> Coffee Maker | B43: =SUMIF('Raw Data'!$G$2:$G$251,Analysis!$A43,'Raw Data'!$O$2:$O$251) -> 3119.61 | C43: =SUMIF('Raw Data'!$G$2:$G$251,Analysis!$A43,'Raw Data'!$I$2:$I$251) -> 39 | E43: Select Product | F43: Coffee Maker
A44: Desk | B44: =SUMIF('Raw Data'!$G$2:$G$251,Analysis!$A44,'Raw Data'!$O$2:$O$251) -> 23399.22 | C44: =SUMIF('Raw Data'!$G$2:$G$251,Analysis!$A44,'Raw Data'!$I$2:$I$251) -> 78 | H44: Total Amount | I44: =SUM('Raw Data'!$O$2:$O$251) -> 229192.47
A45: Bookshelf | B45: =SUMIF('Raw Data'!$G$2:$G$251,Analysis!$A45,'Raw Data'!$O$2:$O$251) -> 15298.98 | C45: =SUMIF('Raw Data'!$G$2:$G$251,Analysis!$A45,'Raw Data'!$I$2:$I$251) -> 102 | E45: Price Amount | F45: {=_xlfn.XLOOKUP(F43,_xlfn.ANCHORARRAY($A$43),$B$43:$B$52)} -> 3119.61 | H45: Expected Growth % | I45: 0.2
A46: Keyboard | B46: =SUMIF('Raw Data'!$G$2:$G$251,Analysis!$A46,'Raw Data'!$O$2:$O$251) -> 8009.11 | C46: =SUMIF('Raw Data'!$G$2:$G$251,Analysis!$A46,'Raw Data'!$I$2:$I$251) -> 89 | E46: Quantity | F46: {=_xlfn.XLOOKUP(F43,_xlfn.ANCHORARRAY(A43),C43:C52)} -> 39 | H46: Final Amount | I46: =I44*(1+I45) -> 275030.96
A47: Headphones | B47: =SUMIF('Raw Data'!$G$2:$G$251,Analysis!$A47,'Raw Data'!$O$2:$O$251) -> 7049.53 | C47: =SUMIF('Raw Data'!$G$2:$G$251,Analysis!$A47,'Raw Data'!$I$2:$I$251) -> 47 | E47: Final Amount | F47: =F45*F46 -> 121664.79
A48: Blender | B48: =SUMIF('Raw Data'!$G$2:$G$251,Analysis!$A48,'Raw Data'!$O$2:$O$251) -> 5219.13 | C48: =SUMIF('Raw Data'!$G$2:$G$251,Analysis!$A48,'Raw Data'!$I$2:$I$251) -> 87
A49: Smartphone | B49: =SUMIF('Raw Data'!$G$2:$G$251,Analysis!$A49,'Raw Data'!$O$2:$O$251) -> 67199.04 | C49: =SUMIF('Raw Data'!$G$2:$G$251,Analysis!$A49,'Raw Data'!$I$2:$I$251) -> 96 | E49: Set Gol change Quantity | H49: Set Gol change Price
A50: Monitor | B50: =SUMIF('Raw Data'!$G$2:$G$251,Analysis!$A50,'Raw Data'!$O$2:$O$251) -> 21999.12 | C50: =SUMIF('Raw Data'!$G$2:$G$251,Analysis!$A50,'Raw Data'!$I$2:$I$251) -> 88
A51: Laptop | B51: =SUMIF('Raw Data'!$G$2:$G$251,Analysis!$A51,'Raw Data'!$O$2:$O$251) -> 67499.25 | C51: =SUMIF('Raw Data'!$G$2:$G$251,Analysis!$A51,'Raw Data'!$I$2:$I$251) -> 75 | E51: Price Amount | F51: =F45 -> 3119.61 | H51: Price Amount | I51: 30769.231
A52: Office Chair | B52: =SUMIF('Raw Data'!$G$2:$G$251,Analysis!$A52,'Raw Data'!$O$2:$O$251) -> 10399.48 | C52: =SUMIF('Raw Data'!$G$2:$G$251,Analysis!$A52,'Raw Data'!$I$2:$I$251) -> 52 | E52: Quantity | F52: 384.66347 | H52: Quantity | I52: =F46 -> 39
E53: Final Amount | F53: =F51*F52 -> 1200000 | H53: Final Amount | I53: =I51*I52 -> 1200000
A56: 4) Conditional Formating
...

Sheet Visualizations
A1: 9) Pivot Table Pivot Chart (Bar , Line, pie) , Kpi and Slicers and Timelines , 10) Data Analysis and Storytelling , 11) report and Dashboard
D3: Top Product | H3: Day Transaction | K3: Customer Segment
A4: TotalRevenue | D4: Product | E4: Amount | H4: Days | I4: Count Transaction | K4: Customer Segment | L4: Count of Customer_Segment
A5: 229192.47 | D5: Laptop | E5: 67499.25 | H5: 45393 | I5: 1 | K5: Basic | L5: 0.296
D6: Smartphone | E6: 67199.04 | H6: 45396 | I6: 1 | K6: Premium | L6: 0.38
D7: Desk | E7: 23399.22 | H7: 45399 | I7: 1 | K7: Standard | L7: 0.324
A8: TotalQuantitySold | D8: Monitor | E8: 21999.12 | H8: 45400 | I8: 2
A9: 753 | D9: Bookshelf | E9: 15298.98 | H9: 45403 | I9: 3
D10: Office Chair | E10: 10399.48 | H10: 45405 | I10: 1 | K10: Daynamic Data Storytelling
D11: Keyboard | E11: 8009.11 | H11: 45408 | I11: 4 | K11: Total Customer | L11: =COUNTA(_xlfn.UNIQUE('Raw Data'!D2:D251)) -> 50 | M11: -
A12: Total Transaction | D12: Headphones | E12: 7049.53 | H12: 45409 | I12: 3 | K12: Best-Performing Product | L12: =MAX(B31) -> 67499.25 | M12: =INDEX($A$31:$A$40,MATCH(L12,$B$31:$B$40,0)) -> Laptop
A13: 250 | D13: Blender | E13: 5219.13 | H13: 45410 | I13: 4 | K13: Top Revenue-Generating Customer | L13: =MAX($E$26:$E$76) -> 15659.65 | M13: =INDEX($D$26:$D$76,MATCH(L13,$E$26:$E$76,0)) -> Mark Carter
D14: Coffee Maker | E14: 3119.61 | H14: 45412 | I14: 1 | K14: Top Payment Preference | L14: =MAX(E19:E22) -> 0.304 | M14: =INDEX(D19:D22,MATCH(L14,E19:E22,0)) -> Cash
H15: 45413 | I15: 1
A16: TOP 10 Customer | H16: 45415 | I16: 1
A17: Customer | B17: Amount | D17: Payment Method Distrbution | H17: 45416 | I17: 1
A18: Mark Carter | B18: 15659.65 | D18: Pyment Method | E18: Count of Payment_Method | H18: 45422 | I18: 1
A19: Edward Mitchell | B19: 11919.77 | D19: Cash | E19: 0.304 | H19: 45424 | I19: 3
A20: Barbara Young | B20: 10649.8 | D20: Credit Card | E20: 0.272 | H20: 45425 | I20: 1
A21: Patricia Moore | B21: 9799.73 | D21: Debit Card | E21: 0.216 | H21: 45427 | I21: 2
A22: Paul Baker | B22: 8309.74 | D22: PayPal | E22: 0.208 | H22: 45428 | I22: 1
A23: Dorothy Nelson | B23: 8269.79 | H23: 45430 | I23: 1
A24: Karen Hill | B24: 8009.77 | D24: Top Customer | H24: 45432 | I24: 1
A25: Daniel King | B25: 7309.8 | D25: Row Labels | E25: Sum of Total_Amount | H25: 45434 | I25: 1
A26: Lawrence Reed | B26: 6989.77 | D26: Mark Carter | E26: 15659.65 | H26: 45435 | I26: 1
A27: Joseph Jackson | B27: 6949.84 | H27: 45438 | I27: 1
H28: 45440 | I28: 1
A29: Top Product | H29: 45441 | I29: 1
A30: Row Labels | B30: Sum of Total_Amount | H30: 45443 | I30: 1
A31: Laptop | B31: 67499.25 | H31: 45444 | I31: 2
A32: Smartphone | B32: 67199.04 | H32: 45446 | I32: 1
A33: Desk | B33: 23399.22 | H33: 45449 | I33: 2
A34: Monitor | B34: 21999.12 | H34: 45450 | I34: 1
A35: Bookshelf | B35: 15298.98 | H35: 45452 | I35: 1
A36: Office Chair | B36: 10399.48 | H36: 45456 | I36: 1
A37: Keyboard | B37: 8009.11 | H37: 45459 | I37: 3
A38: Headphones | B38: 7049.53 | H38: 45460 | I38: 2
A39: Blender | B39: 5219.13 | H39: 45468 | I39: 1
A40: Coffee Maker | B40: 3119.61 | H40: 45469 | I40: 2
H41: 45471 | I41: 2
...

Sheet Scenario Summary
B2: Scenario Summary
D3: Current Values: | E3: Bast Case | F3: Normal | G3: Worst Case
E4: Created by himanshi on 09-10-2026 Modified by himanshi on 09-10-2026 | F4: Created by himanshi on 09-10-2026 Modified by himanshi on 09-10-2026 | G4: Created by himanshi on 09-10-2026
B5: Changing Cells:
C6: $I$45 | D6: 0.2 | E6: 0.2 | F6: 0.1 | G6: -0.1
B7: Result Cells:
C8: $I$46 | D8: 275030.96 | E8: 275030.96 | F8: 252111.72 | G8: 206273.22
B9: Notes: Current Values column represents values of changing cells at
B10: time Scenario Summary Report was created. Changing cells for each
B11: scenario are highlighted in gray.

Sheet Raw Data
A1: Transaction_ID | B1: Date | C1: Months | D1: Customer_ID | E1: Customer_Name | F1: Product_ID | G1: Product_Name | H1: Category | I1: Quantity | J1: Unit_Price | K1: Payment_Method | L1: Region | M1: Customer_Segment | N1: Customer_Since | O1: Total_Amount
A2: TRX0001 | B2: 45528 | C2: =TEXT(B2,"mmmm") -> August | D2: CUST039 | E2: Lawrence Reed | F2: P004 | G2: Coffee Maker | H2: Appliances | I2: 3 | J2: 79.99 | K2: Cash | L2: Central | M2: Premium | N2: 44779 | O2: 239.97
A3: TRX0002 | B3: 45501 | C3: =TEXT(B3,"mmmm") -> July | D3: CUST019 | E3: Daniel King | F3: P007 | G3: Desk | H3: Furniture | I3: 3 | J3: 299.99 | K3: Cash | L3: Central | M3: Basic | N3: 44732 | O3: 899.97
A4: TRX0003 | B4: 45737 | C4: =TEXT(B4,"mmmm") -> March | D4: CUST002 | E4: Emma Wilson | F4: P008 | G4: Bookshelf | H4: Furniture | I4: 2 | J4: 149.99 | K4: Cash | L4: West | M4: Premium | N4: 45233 | O4: 299.98
A5: TRX0004 | B5: 45424 | C5: =TEXT(B5,"mmmm") -> May | D5: CUST012 | E5: Patricia Moore | F5: P010 | G5: Keyboard | H5: Electronics | I5: 5 | J5: 89.99 | K5: Cash | L5: North | M5: Premium | N5: 44919 | O5: 449.95
A6: TRX0005 | B6: 45550 | C6: =TEXT(B6,"mmmm") -> September | D6: CUST042 | E6: Ruth Brooks | F6: P003 | G6: Headphones | H6: Electronics | I6: 4 | J6: 149.99 | K6: Cash | L6: North | M6: Basic | N6: 44909 | O6: 599.96
A7: TRX0006 | B7: 45498 | C7: =TEXT(B7,"mmmm") -> July | D7: CUST007 | E7: David Martinez | F7: P005 | G7: Blender | H7: Appliances | I7: 2 | J7: 59.99 | K7: Cash | L7: North | M7: Standard | N7: 45152 | O7: 119.98
A8: TRX0007 | B8: 45469 | C8: =TEXT(B8,"mmmm") -> June | D8: CUST009 | E8: Robert Thomas | F8: P010 | G8: Keyboard | H8: Electronics | I8: 2 | J8: 89.99 | K8: Cash | L8: West | M8: Basic | N8: 44438 | O8: 179.98
A9: TRX0008 | B9: 45648 | C9: =TEXT(B9,"mmmm") -> December | D9: CUST007 | E9: David Martinez | F9: P008 | G9: Bookshelf | H9: Furniture | I9: 3 | J9: 149.99 | K9: Debit Card | L9: North | M9: Standard | N9: 44522 | O9: 449.97
A10: TRX0009 | B10: 45588 | C10: =TEXT(B10,"mmmm") -> October | D10: CUST004 | E10: Sarah Davis | F10: P002 | G10: Smartphone | H10: Electronics | I10: 2 | J10: 699.99 | K10: Cash | L10: Central | M10: Basic | N10: 44992 | O10: 1399.98
A11: TRX0010 | B11: 45688 | C11: =TEXT(B11,"mmmm") -> January | D11: CUST026 | E11: Karen Hill | F11: P002 | G11: Smartphone | H11: Electronics | I11: 4 | J11: 699.99 | K11: Debit Card | L11: West | M11: Premium | N11: 44692 | O11: 2799.96
A12: TRX0011 | B12: 45696 | C12: =TEXT(B12,"mmmm") -> February | D12: CUST040 | E12: Sharon Butler | F12: P005 | G12: Blender | H12: Appliances | I12: 5 | J12: 59.99 | K12: Debit Card | L12: Central | M12: Standard | N12: 45177 | O12: 299.95
A13: TRX0012 | B13: 45622 | C13: =TEXT(B13,"mmmm") -> November | D13: CUST045 | E13: Douglas Watson | F13: P009 | G13: Monitor | H13: Electronics | I13: 5 | J13: 249.99 | K13: Credit Card | L13: North | M13: Basic | N13: 44873 | O13: 1249.95
... A251: TRX0250 | B251: 45746 | C251: =TEXT(B251,"mmmm") -> March | D251: CUST026 | E251: Karen Hill | F251: P010 | G251: Keyboard | H251: Electronics | I251: 2 | J251: 89.99 | K251: Debit Card | L251: West | M251: Premium | N251: 44522 | O251: 179.98
